Workbook
Name RF_3: Workload!$E$7
Name UniqueData1: Workload!$C$39
Name EachSISize2: Workload!$D$47
Name PISizeOnDisk3: Workload!$E$44
Name PIReadIOPerWrite1: Workload!$C$76
Name DataFootprint2: Workload!$D$51
Name InstanceDiskCount: Custom!$C$14
Name SprigsPerPartition2: Workload!$D$43
Name PeakDiskWriteThroughput1: Workload!$C$85
Name DataReadIOPerRead5: Workload!$G$73
Name DiskUtilisation: Workload!$C$59
Name SIWriteIOPerWrite4: Workload!$F$79
Name InstanceRamSize: AWS!$F$4
Name AvgRecordSize3: Workload!$E$38
Name PIStorage5: Workload!$G$27
Name AvgObjRPS1: Workload!$C$21
Name SIStorage5: Workload!$G$28
Name DiskOverprovisioning: AWS!$C$12
Name SIStorage3: Workload!$E$28
Name PIReadIOPerRead1: Workload!$C$77
Name SIReadIOPerQuery1: Workload!$C$81
Name UniqueData3: Workload!$E$39
Name NodeCount: Custom!$C$10
Name AZTransferByWriteReplication: Custom!$C$41
Name DataReadIOPerRead1: Workload!$C$73
Name AvgObjPerRecord1: Workload!$C$12
Name PeakDiskWriteThroughput2: Workload!$D$85
Name PIWriteIOPerWrite2: Workload!$D$75
Name PeakObjWPS2: Workload!$D$25
Name PeakDiskReadIOPS2: Workload!$D$89
Name SICoverage4: Workload!$F$16
Name ResiliencyTarget: Custom!$C$3
Name SprigsPerPartition5: Workload!$G$43
Name DataStorage2: Workload!$D$29
Name PeakObjRPS3: Workload!$E$22
Name UniqueData2: Workload!$D$39
Name SIWriteIOPerWrite2: Workload!$D$79
Name PIReadIOPerRead3: Workload!$E$77
Name PIStorage3: Workload!$E$27
Name RecordCount4: Workload!$F$40
Name PeakWriteIOPS: Workload!$C$96
Name NotFoundRate2: Workload!$D$19
Name DataStorage4: Workload!$F$29
Name PISizeInRam2: Workload!$D$42
Name NumberOfSIs5: Workload!$G$15
Name RegionTransferCost: #REF!
Name NetWorkCost: Custom!$C$52
Name PIReadIOPerWrite2: Workload!$D$76
Name PeakDiskReadThroughput2: Workload!$D$86
Name SprigsPerPartition3: Workload!$E$43
Name PageCacheRate1: Workload!$C$20
Name PIStorage1: Workload!$C$27
Name RecordCount3: Workload!$E$40
Name RecordsPerSprig: Miscellaneous!$C$13
Name DataFootprint5: Workload!$G$51
Name EachSISize4: Workload!$F$47
Name NodeFailure: Custom!$C$4
Name SIEntries2: Workload!$D$46
Name CostPerRegion: Custom!$C$50
Name PeakDiskReadIOPS5: Workload!$G$89

Sheet Workload
B1: How to: Aerospike Sizing Estimator
A3: Workload Specification
B5: Use Cases | C5: One | D5: Two | E5: Three | F5: Four | G5: Five
B6: Resilience
B7: Replication Factor | C7: 3 | D7: 2 | E7: 2 | F7: 2 | G7: 2
B8: Domain Model Specification
B9: Average Object size (B) | C9: 1024 | D9: 0 | E9: 0 | F9: 0 | G9: 0
B10: Object Count | C10: 1200000000 | D10: 0 | E10: 0 | F10: 0 | G10: 0
B11: Data Model Specification
B12: Average Number of Objects per Record | C12: 1 | D12: 1 | E12: 1 | F12: 1 | G12: 1
B13: Compression Reduction | C13: 0 | D13: 0 | E13: 0 | F13: 0 | G13: 0
B14: Secondary Index Specification
B15: Number of Secondary Indexes | C15: 0 | D15: 1 | E15: 0 | F15: 0 | G15: 0
B16: Average SI Entry Per Object | C16: 1 | D16: 1 | E16: 1 | F16: 1 | G16: 1
B17: Peak SI Query | C17: 400 | D17: 0 | E17: 0 | F17: 0 | G17: 0
B18: Read Throughput Specification
B19: Not Found Rate | C19: 0 | D19: 0 | E19: 0 | F19: 0 | G19: 0
B20: Page Cache Hit Rate | C20: 0 | D20: 0 | E20: 0 | F20: 0 | G20: 0
B21: Average Reads Per Second | C21: 1000000 | D21: 0 | E21: 0 | F21: 0 | G21: 0
B22: Peak Reads Per Second | C22: 1000000 | D22: 0 | E22: 0 | F22: 0 | G22: 0
B23: Write Throughput Specification
B24: Average Writes Per Second | C24: 20000 | D24: 0 | E24: 0 | F24: 0 | G24: 0
B25: Peak Writes Per Second | C25: 80000 | D25: 0 | E25: 0 | F25: 0 | G25: 0
B26: Storage Specification
B27: Primary Index Storage | C27: Ram | D27: Ram | E27: Ram | F27: Ram | G27: Ram
B28: Secondary Index Storage | C28: Ram | D28: Ram | E28: Ram | F28: Ram | G28: Ram
B29: Data Storage | C29: Disk | D29: Disk | E29: Disk | F29: Disk | G29: Disk
B30: SI On Disk
B31: Cached Levels of SI on Disk BTree | C31: 2 | D31: 2 | E31: 2 | F31: 2 | G31: 2
A34: Resource Size Estimation
B36: Use Cases | C36: One | D36: Two | E36: Three | F36: Four | G36: Five
B37: Data Model Detail
B38: Average Record Size (B) | C38: =AvgObjSize1 * AvgObjPerRecord1 -> 1024 | D38: =AvgObjSize2 * AvgObjPerRecord2 -> 0 | E38: =AvgObjSize3 * AvgObjPerRecord3 -> 0 | F38: =AvgObjSize4 * AvgObjPerRecord4 -> 0 | G38: =AvgObjSize5 * AvgObjPerRecord5 -> 0
B39: Unique Data Size (GB) | C39: =ObjCount1*AvgObjSize1/GB -> 1144.4092 | D39: =ObjCount2*AvgObjSize2/GB -> 0 | E39: =ObjCount3*AvgObjSize3/GB -> 0 | F39: =ObjCount4*AvgObjSize4/GB -> 0 | G39: =ObjCount5*AvgObjSize5/GB -> 0
B40: Record Count (M) | C40: =IFERROR(ObjCount1/AvgObjPerRecord1, 0) -> 1200000000 | D40: =IFERROR(ObjCount2/AvgObjPerRecord2, 0) -> 0 | E40: =IFERROR(ObjCount3/AvgObjPerRecord3, 0) -> 0 | F40: =IFERROR(ObjCount4/AvgObjPerRecord4, 0) -> 0 | G40: =IFERROR(ObjCount5/AvgObjPerRecord5, 0) -> 0
B41: Primary Index Detail (Replication Factor Not Included)
B42: Primary index Size In Ram (GB) | C42: =If(PIStorage1="Ram", RecordCount1*PIEntrySize/GB, 0) -> 71.525574 | D42: =If(PIStorage2="Ram", RecordCount2*PIEntrySize/GB, 0) -> 0 | E42: =If(PIStorage3="Ram", RecordCount3*PIEntrySize/GB, 0) -> 0 | F42: =If(PIStorage4="Ram", RecordCount4*PIEntrySize/GB, 0) -> 0 | G42: =If(PIStorage5="Ram", RecordCount5*PIEntrySize/GB, 0) -> 0
B43: Sprigs Required Per Partition | C43: =If(PIStorage1="Disk", IFERROR( 2 ^ CEILING( LOG((RecordCount1/(RecordsPerSprig*PIFillFactor))/Partitions, 2), 1), 0), 0) -> 0 | D43: =If(PIStorage2="Disk", IFERROR( 2 ^ CEILING( LOG((RecordCount2/(RecordsPerSprig*PIFillFactor))/Partitions, 2), 1), 0), 0) -> 0 | E43: =If(PIStorage3="Disk", IFERROR( 2 ^ CEILING( LOG((RecordCount3/(RecordsPerSprig*PIFillFactor))/Partitions, 2), 1), 0), 0) -> 0 | F43: =If(PIStorage4="Disk", IFERROR( 2 ^ CEILING( LOG((RecordCount4/(RecordsPerSprig*PIFillFactor))/Partitions, 2), 1), 0), 0) -> 0 | G43: =If(PIStorage5="Disk", IFERROR( 2 ^ CEILING( LOG((RecordCount5/(RecordsPerSprig*PIFillFactor))/Partitions, 2), 1), 0), 0) -> 0
B44: Primary index Size On Disk (GB) | C44: =If(PIStorage1="Disk", SprigsPerPartition1*Partitions*SprigSize/GB, 0) -> 0 | D44: =If(PIStorage2="Disk", SprigsPerPartition2*Partitions*SprigSize/GB, 0) -> 0 | E44: =If(PIStorage3="Disk", SprigsPerPartition3*Partitions*SprigSize/GB, 0) -> 0 | F44: =If(PIStorage4="Disk", SprigsPerPartition4*Partitions*SprigSize/GB, 0) -> 0 | G44: =If(PIStorage5="Disk", SprigsPerPartition5*Partitions*SprigSize/GB, 0) -> 0
B45: Secondary Index Detail (Replication Factor Not Included)
...

Sheet AWS
B2: Resilience | E2: Instance Resources | H2: EC2 Family | I2: Lower Bound $ | M2: EC2 Family | N2: Disk To Ram Ratio | V2: EC2 Instance Types (Prices are for the us-east-1 region) | AD2: =if(Miscellaneous!E2*AWS!C$5> 256, "", Miscellaneous!E2*AWS!C$5) -> 0 | AE2: =IFERROR(__xludf.DUMMYFUNCTION(" filter(Miscellaneous!E2:E12, Miscellaneous!E2:E12<Workload!$C$7)"),0.0) -> 0 | AF2: =IFERROR(__xludf.DUMMYFUNCTION(" filter(Miscellaneous!E2:E12, Miscellaneous!E2:E12<AWS!$C$5)"),0.0) -> 0
B3: Resiliency Target | C3: Rack/AZ | E3: Number of vCPUs | F3: =VLOOKUP(InstanceType,AWS!V4:AB780,2, False) -> 1 | H3: {=Sort(J3:K114, 2, true)} -> i4g | I3: 1463.25 | J3: a1 | K3: =If(C$20 = 0, Ceiling(($C$19 / VLOOKUp(Concat("$", Concat(J3, ".Search")) ,U$4:AB$780, 4, false) * VLOOKUp(Concat("$", Concat(J3, ".Search")) ,U$4:AB$780, 8, false) / AZ),1) * AZ, If(VLOOKUp(Concat("$", Concat(J3, ".Search")) ,U$4:AB$780, 5, false) = 0 , "N/A", Max( Ceiling(($C$20 / (VLOOKUp(Concat("$", Concat(J3, ".Search")) ,U$4:AB$780, 5, false) * VLOOKUp(Concat("$", Concat(J3, ".Search")) ,U$4:AB$780, 6, false)* (1 - DiskOverprovisioning))) / AZ,1) * AZ , Ceiling(($C$19 / VLOOKUp(Concat("$", Concat(J3, ".Search")) ,U$4:AB$780, 4, false) / AZ),1) * AZ ) * VLOOKUp(Concat("$", Concat(J3, ".Search")) ,U$4:AB$780, 8, false) ) ) -> N/A | M3: {=Sort(Q3:S114, 3, true)} -> i3 | N3: 26.47541 | O3: 0.36278683 | P3: =VLOOKUp(Concat("$", Concat(Q3, ".Search")) ,U$4:AB$780, 5, false) * VLOOKUp(Concat("$", Concat(Q3, ".Search")) ,U$4:AB$780, 6, false) * (1 - $C$12)/ VLOOKUp(Concat("$", Concat(Q3, ".Search")) ,U$4:AB$780, 4, false) -> 0 | Q3: a1 | R3: =if(P3=0, "N/A", P3) -> N/A | S3: =if(P3=0, "N/A", Abs(P3-$C$21)) -> N/A | U3: Family | V3: Name | W3: vCPU | X3: Memory (GB) | Y3: Storage (GB) | Z3: Number Of Disks | AA3: Network Bandwidth | AB3: Monthly Reserved rate | AD3: =if(Miscellaneous!E3*AWS!C$5> 256, "", Miscellaneous!E3*AWS!C$5) -> 1 | AE3: =IFERROR(__xludf.DUMMYFUNCTION("""COMPUTED_VALUE"""),1.0) -> 1
B4: Tolerated Node Failures Count | C4: 1 | E4: Ram (GB) | F4: =VLOOKUP(InstanceType,AWS!V4:AB780,3, False) -> 3.75 | H4: i3 | I4: 1562.2 | J4: c3 | K4: =If(C$20 = 0, Ceiling(($C$19 / VLOOKUp(Concat("$", Concat(J4, ".Search")) ,U$4:AB$780, 4, false) * VLOOKUp(Concat("$", Concat(J4, ".Search")) ,U$4:AB$780, 8, false) / AZ),1) * AZ, If(VLOOKUp(Concat("$", Concat(J4, ".Search")) ,U$4:AB$780, 5, false) = 0 , "N/A", Max( Ceiling(($C$20 / (VLOOKUp(Concat("$", Concat(J4, ".Search")) ,U$4:AB$780, 5, false) * VLOOKUp(Concat("$", Concat(J4, ".Search")) ,U$4:AB$780, 6, false)* (1 - DiskOverprovisioning))) / AZ,1) * AZ , Ceiling(($C$19 / VLOOKUp(Concat("$", Concat(J4, ".Search")) ,U$4:AB$780, 4, false) / AZ),1) * AZ ) * VLOOKUp(Concat("$", Concat(J4, ".Search")) ,U$4:AB$780, 8, false) ) ) -> 12150.12 | M4: c6gd | N4: 25.234375 | O4: 1.6038217 | P4: =VLOOKUp(Concat("$", Concat(Q4, ".Search")) ,U$4:AB$780, 5, false) * VLOOKUp(Concat("$", Concat(Q4, ".Search")) ,U$4:AB$780, 6, false) * (1 - $C$12)/ VLOOKUp(Concat("$", Concat(Q4, ".Search")) ,U$4:AB$780, 4, false) -> 9.0666667 | Q4: c3 | R4: =if(P4=0, "N/A", P4) -> 9.0666667 | S4: =if(P4=0, "N/A", Abs(P4-$C$21)) -> 17.77153 | U4: $a1.Search | V4: a1.medium | W4: 1 | X4: 2 | Y4: 0 | Z4: 0 | AA4: Up to 10 Gigabit | AB4: 11.75 | AD4: =if(Miscellaneous!E4*AWS!C$5> 256, "", Miscellaneous!E4*AWS!C$5) -> 2 | AE4: =IFERROR(__xludf.DUMMYFUNCTION("""COMPUTED_VALUE"""),2.0) -> 2
B5: Racks or Availability Zones Count | C5: 1 | E5: Number of Disks | F5: =VLOOKUP(InstanceType,AWS!V4:AB780,5, False) -> 0.05 | H5: i4i | I5: 1624.25 | J5: c4 | K5: =If(C$20 = 0, Ceiling(($C$19 / VLOOKUp(Concat("$", Concat(J5, ".Search")) ,U$4:AB$780, 4, false) * VLOOKUp(Concat("$", Concat(J5, ".Search")) ,U$4:AB$780, 8, false) / AZ),1) * AZ, If(VLOOKUp(Concat("$", Concat(J5, ".Search")) ,U$4:AB$780, 5, false) = 0 , "N/A", Max( Ceiling(($C$20 / (VLOOKUp(Concat("$", Concat(J5, ".Search")) ,U$4:AB$780, 5, false) * VLOOKUp(Concat("$", Concat(J5, ".Search")) ,U$4:AB$780, 6, false)* (1 - DiskOverprovisioning))) / AZ,1) * AZ , Ceiling(($C$19 / VLOOKUp(Concat("$", Concat(J5, ".Search")) ,U$4:AB$780, 4, false) / AZ),1) * AZ ) * VLOOKUp(Concat("$", Concat(J5, ".Search")) ,U$4:AB$780, 8, false) ) ) -> N/A | M5: c6id | N5: 25.234375 | O5: 1.6038217 | P5: =VLOOKUp(Concat("$", Concat(Q5, ".Search")) ,U$4:AB$780, 5, false) * VLOOKUp(Concat("$", Concat(Q5, ".Search")) ,U$4:AB$780, 6, false) * (1 - $C$12)/ VLOOKUp(Concat("$", Concat(Q5, ".Search")) ,U$4:AB$780, 4, false) -> 0 | Q5: c4 | R5: =if(P5=0, "N/A", P5) -> N/A | S5: =if(P5=0, "N/A", Abs(P5-$C$21)) -> N/A | U5: $a1. | V5: a1.large | W5: 2 | X5: 4 | Y5: 0 | Z5: 0 | AA5: Up to 10 Gigabit | AB5: 23.43 | AD5: =if(Miscellaneous!E5*AWS!C$5> 256, "", Miscellaneous!E5*AWS!C$5) -> 3
B6: Tolerated AZ/Rack Failures Count | C6: 0 | E6: Total Disk Size (GB) | F6: =VLOOKUP(InstanceType,AWS!V4:AB780,4, False)*InstanceDiskCount -> 4 | H6: i8g | I6: 1650.95 | J6: c5 | K6: =If(C$20 = 0, Ceiling(($C$19 / VLOOKUp(Concat("$", Concat(J6, ".Search")) ,U$4:AB$780, 4, false) * VLOOKUp(Concat("$", Concat(J6, ".Search")) ,U$4:AB$780, 8, false) / AZ),1) * AZ, If(VLOOKUp(Concat("$", Concat(J6, ".Search")) ,U$4:AB$780, 5, false) = 0 , "N/A", Max( Ceiling(($C$20 / (VLOOKUp(Concat("$", Concat(J6, ".Search")) ,U$4:AB$780, 5, false) * VLOOKUp(Concat("$", Concat(J6, ".Search")) ,U$4:AB$780, 6, false)* (1 - DiskOverprovisioning))) / AZ,1) * AZ , Ceiling(($C$19 / VLOOKUp(Concat("$", Concat(J6, ".Search")) ,U$4:AB$780, 4, false) / AZ),1) * AZ ) * VLOOKUp(Concat("$", Concat(J6, ".Search")) ,U$4:AB$780, 8, false) ) ) -> N/A | M6: c7gd | N6: 25.234375 | O6: 1.6038217 | P6: =VLOOKUp(Concat("$", Concat(Q6, ".Search")) ,U$4:AB$780, 5, false) * VLOOKUp(Concat("$", Concat(Q6, ".Search")) ,U$4:AB$780, 6, false) * (1 - $C$12)/ VLOOKUp(Concat("$", Concat(Q6, ".Search")) ,U$4:AB$780, 4, false) -> 0 | Q6: c5 | R6: =if(P6=0, "N/A", P6) -> N/A | S6: =if(P6=0, "N/A", Abs(P6-$C$21)) -> N/A | U6: $a1. | V6: a1.xlarge | W6: 4 | X6: 8 | Y6: 0 | Z6: 0 | AA6: Up to 10 Gigabit | AB6: 46.94 | AD6: =if(Miscellaneous!E6*AWS!C$5> 256, "", Miscellaneous!E6*AWS!C$5) -> 4
B7: Allow Read from Nearest Rack/AZ | C7: FALSE | E7: Throughput per Disk (MB/s) | F7: 1500 | H7: i7i | I7: 1815.95 | J7: c5a | K7: =If(C$20 = 0, Ceiling(($C$19 / VLOOKUp(Concat("$", Concat(J7, ".Search")) ,U$4:AB$780, 4, false) * VLOOKUp(Concat("$", Concat(J7, ".Search")) ,U$4:AB$780, 8, false) / AZ),1) * AZ, If(VLOOKUp(Concat("$", Concat(J7, ".Search")) ,U$4:AB$780, 5, false) = 0 , "N/A", Max( Ceiling(($C$20 / (VLOOKUp(Concat("$", Concat(J7, ".Search")) ,U$4:AB$780, 5, false) * VLOOKUp(Concat("$", Concat(J7, ".Search")) ,U$4:AB$780, 6, false)* (1 - DiskOverprovisioning))) / AZ,1) * AZ , Ceiling(($C$19 / VLOOKUp(Concat("$", Concat(J7, ".Search")) ,U$4:AB$780, 4, false) / AZ),1) * AZ ) * VLOOKUp(Concat("$", Concat(J7, ".Search")) ,U$4:AB$780, 8, false) ) ) -> N/A | M7: c8gd | N7: 25.234375 | O7: 1.6038217 | P7: =VLOOKUp(Concat("$", Concat(Q7, ".Search")) ,U$4:AB$780, 5, false) * VLOOKUp(Concat("$", Concat(Q7, ".Search")) ,U$4:AB$780, 6, false) * (1 - $C$12)/ VLOOKUp(Concat("$", Concat(Q7, ".Search")) ,U$4:AB$780, 4, false) -> 0 | Q7: c5a | R7: =if(P7=0, "N/A", P7) -> N/A | S7: =if(P7=0, "N/A", Abs(P7-$C$21)) -> N/A | U7: $a1. | V7: a1.2xlarge | W7: 8 | X7: 16 | Y7: 0 | Z7: 0 | AA7: Up to 10 Gigabit | AB7: 93.81 | AD7: =if(Miscellaneous!E7*AWS!C$5> 256, "", Miscellaneous!E7*AWS!C$5) -> 5
E8: IOPS per Disk (K) | F8: 320 | H8: i3en | I8: 2023.56 | J8: c5ad | K8: =If(C$20 = 0, Ceiling(($C$19 / VLOOKUp(Concat("$", Concat(J8, ".Search")) ,U$4:AB$780, 4, false) * VLOOKUp(Concat("$", Concat(J8, ".Search")) ,U$4:AB$780, 8, false) / AZ),1) * AZ, If(VLOOKUp(Concat("$", Concat(J8, ".Search")) ,U$4:AB$780, 5, false) = 0 , "N/A", Max( Ceiling(($C$20 / (VLOOKUp(Concat("$", Concat(J8, ".Search")) ,U$4:AB$780, 5, false) * VLOOKUp(Concat("$", Concat(J8, ".Search")) ,U$4:AB$780, 6, false)* (1 - DiskOverprovisioning))) / AZ,1) * AZ , Ceiling(($C$19 / VLOOKUp(Concat("$", Concat(J8, ".Search")) ,U$4:AB$780, 4, false) / AZ),1) * AZ ) * VLOOKUp(Concat("$", Concat(J8, ".Search")) ,U$4:AB$780, 8, false) ) ) -> 5063.28 | M8: i4g | N8: 24.902344 | O8: 1.9358529 | P8: =VLOOKUp(Concat("$", Concat(Q8, ".Search")) ,U$4:AB$780, 5, false) * VLOOKUp(Concat("$", Concat(Q8, ".Search")) ,U$4:AB$780, 6, false) * (1 - $C$12)/ VLOOKUp(Concat("$", Concat(Q8, ".Search")) ,U$4:AB$780, 4, false) -> 15.9375 | Q8: c5ad | R8: =if(P8=0, "N/A", P8) -> 15.9375 | S8: =if(P8=0, "N/A", Abs(P8-$C$21)) -> 10.900697 | U8: $a1. | V8: a1.4xlarge | W8: 16 | X8: 32 | Y8: 0 | Z8: 0 | AA8: Up to 10 Gigabit | AB8: 187.61 | AD8: =if(Miscellaneous!E8*AWS!C$5> 256, "", Miscellaneous!E8*AWS!C$5) -> 6
B9: EC2 Specification | E9: Total IOPS (K) | F9: =AWSDiskIOPS*InstanceDiskCount -> 16 | H9: i7ie | I9: 2250.45 | J9: c5d | K9: =If(C$20 = 0, Ceiling(($C$19 / VLOOKUp(Concat("$", Concat(J9, ".Search")) ,U$4:AB$780, 4, false) * VLOOKUp(Concat("$", Concat(J9, ".Search")) ,U$4:AB$780, 8, false) / AZ),1) * AZ, If(VLOOKUp(Concat("$", Concat(J9, ".Search")) ,U$4:AB$780, 5, false) = 0 , "N/A", Max( Ceiling(($C$20 / (VLOOKUp(Concat("$", Concat(J9, ".Search")) ,U$4:AB$780, 5, false) * VLOOKUp(Concat("$", Concat(J9, ".Search")) ,U$4:AB$780, 6, false)* (1 - DiskOverprovisioning))) / AZ,1) * AZ , Ceiling(($C$19 / VLOOKUp(Concat("$", Concat(J9, ".Search")) ,U$4:AB$780, 4, false) / AZ),1) * AZ ) * VLOOKUp(Concat("$", Concat(J9, ".Search")) ,U$4:AB$780, 8, false) ) ) -> 8744.67 | M9: i4i | N9: 24.902344 | O9: 1.9358529 | P9: =VLOOKUp(Concat("$", Concat(Q9, ".Search")) ,U$4:AB$780, 5, false) * VLOOKUp(Concat("$", Concat(Q9, ".Search")) ,U$4:AB$780, 6, false) * (1 - $C$12)/ VLOOKUp(Concat("$", Concat(Q9, ".Search")) ,U$4:AB$780, 4, false) -> 10.625 | Q9: c5d | R9: =if(P9=0, "N/A", P9) -> 10.625 | S9: =if(P9=0, "N/A", Abs(P9-$C$21)) -> 16.213197 | U9: $c3. | V9: c3.large | W9: 2 | X9: 3.75 | Y9: 320 | Z9: =0.1 -> 0.1 | AA9: Moderate | AB9: 53.29 | AD9: =if(Miscellaneous!E9*AWS!C$5> 256, "", Miscellaneous!E9*AWS!C$5) -> 7
B10: Instance Type | C10: m3.medium | E10: Total Throughput (MB/s) | F10: =AWSDiskThroughput*InstanceDiskCount -> 75 | H10: c6gd | I10: 2825.8 | J10: c5n | K10: =If(C$20 = 0, Ceiling(($C$19 / VLOOKUp(Concat("$", Concat(J10, ".Search")) ,U$4:AB$780, 4, false) * VLOOKUp(Concat("$", Concat(J10, ".Search")) ,U$4:AB$780, 8, false) / AZ),1) * AZ, If(VLOOKUp(Concat("$", Concat(J10, ".Search")) ,U$4:AB$780, 5, false) = 0 , "N/A", Max( Ceiling(($C$20 / (VLOOKUp(Concat("$", Concat(J10, ".Search")) ,U$4:AB$780, 5, false) * VLOOKUp(Concat("$", Concat(J10, ".Search")) ,U$4:AB$780, 6, false)* (1 - DiskOverprovisioning))) / AZ,1) * AZ , Ceiling(($C$19 / VLOOKUp(Concat("$", Concat(J10, ".Search")) ,U$4:AB$780, 4, false) / AZ),1) * AZ ) * VLOOKUp(Concat("$", Concat(J10, ".Search")) ,U$4:AB$780, 8, false) ) ) -> N/A | M10: i7i | N10: 24.902344 | O10: 1.9358529 | P10: =VLOOKUp(Concat("$", Concat(Q10, ".Search")) ,U$4:AB$780, 5, false) * VLOOKUp(Concat("$", Concat(Q10, ".Search")) ,U$4:AB$780, 6, false) * (1 - $C$12)/ VLOOKUp(Concat("$", Concat(Q10, ".Search")) ,U$4:AB$780, 4, false) -> 0 | Q10: c5n | R10: =if(P10=0, "N/A", P10) -> N/A | S10: =if(P10=0, "N/A", Abs(P10-$C$21)) -> N/A | U10: $c3. | V10: c3.xlarge | W10: 4 | X10: 7.5 | Y10: 320 | Z10: =1/4 -> 0.25 | AA10: Moderate | AB10: 106.58 | AD10: =if(Miscellaneous!E10*AWS!C$5> 256, "", Miscellaneous!E10*AWS!C$5) -> 8
B11: Number of Instances | C11: 4 | E11: Network Bandwidth | F11: =VLOOKUP(InstanceType,AWS!V4:AB780,6, False) -> Moderate | H11: im4gn | I11: 3065.76 | J11: c6a | K11: =If(C$20 = 0, Ceiling(($C$19 / VLOOKUp(Concat("$", Concat(J11, ".Search")) ,U$4:AB$780, 4, false) * VLOOKUp(Concat("$", Concat(J11, ".Search")) ,U$4:AB$780, 8, false) / AZ),1) * AZ, If(VLOOKUp(Concat("$", Concat(J11, ".Search")) ,U$4:AB$780, 5, false) = 0 , "N/A", Max( Ceiling(($C$20 / (VLOOKUp(Concat("$", Concat(J11, ".Search")) ,U$4:AB$780, 5, false) * VLOOKUp(Concat("$", Concat(J11, ".Search")) ,U$4:AB$780, 6, false)* (1 - DiskOverprovisioning))) / AZ,1) * AZ , Ceiling(($C$19 / VLOOKUp(Concat("$", Concat(J11, ".Search")) ,U$4:AB$780, 4, false) / AZ),1) * AZ ) * VLOOKUp(Concat("$", Concat(J11, ".Search")) ,U$4:AB$780, 8, false) ) ) -> N/A | M11: i8g | N11: 24.902344 | O11: 1.9358529 | P11: =VLOOKUp(Concat("$", Concat(Q11, ".Search")) ,U$4:AB$780, 5, false) * VLOOKUp(Concat("$", Concat(Q11, ".Search")) ,U$4:AB$780, 6, false) * (1 - $C$12)/ VLOOKUp(Concat("$", Concat(Q11, ".Search")) ,U$4:AB$780, 4, false) -> 0 | Q11: c6a | R11: =if(P11=0, "N/A", P11) -> N/A | S11: =if(P11=0, "N/A", Abs(P11-$C$21)) -> N/A | U11: $c3.Search | V11: c3.2xlarge | W11: 8 | X11: 15 | Y11: 320 | Z11: =1/2 -> 0.5 | AA11: High | AB11: 213.16 | AD11: =if(Miscellaneous!E11*AWS!C$5> 256, "", Miscellaneous!E11*AWS!C$5) -> 9
B12: Disk Overprovisioning | C12: 0.15 | E12: Monthly Reserved rate | F12: =VLOOKUP(InstanceType,AWS!V4:AB780,7, False) -> 35.04 | H12: m6gd | I12: 3325.9 | J12: c6g | K12: =If(C$20 = 0, Ceiling(($C$19 / VLOOKUp(Concat("$", Concat(J12, ".Search")) ,U$4:AB$780, 4, false) * VLOOKUp(Concat("$", Concat(J12, ".Search")) ,U$4:AB$780, 8, false) / AZ),1) * AZ, If(VLOOKUp(Concat("$", Concat(J12, ".Search")) ,U$4:AB$780, 5, false) = 0 , "N/A", Max( Ceiling(($C$20 / (VLOOKUp(Concat("$", Concat(J12, ".Search")) ,U$4:AB$780, 5, false) * VLOOKUp(Concat("$", Concat(J12, ".Search")) ,U$4:AB$780, 6, false)* (1 - DiskOverprovisioning))) / AZ,1) * AZ , Ceiling(($C$19 / VLOOKUp(Concat("$", Concat(J12, ".Search")) ,U$4:AB$780, 4, false) / AZ),1) * AZ ) * VLOOKUp(Concat("$", Concat(J12, ".Search")) ,U$4:AB$780, 8, false) ) ) -> N/A | M12: g5 | N12: 16.822917 | O12: 10.01528 | P12: =VLOOKUp(Concat("$", Concat(Q12, ".Search")) ,U$4:AB$780, 5, false) * VLOOKUp(Concat("$", Concat(Q12, ".Search")) ,U$4:AB$780, 6, false) * (1 - $C$12)/ VLOOKUp(Concat("$", Concat(Q12, ".Search")) ,U$4:AB$780, 4, false) -> 0 | Q12: c6g | R12: =if(P12=0, "N/A", P12) -> N/A | S12: =if(P12=0, "N/A", Abs(P12-$C$21)) -> N/A | U12: $c3. | V12: c3.4xlarge | W12: 16 | X12: 30 | Y12: 320 | Z12: 1 | AA12: High | AB12: 426.32 | AD12: =if(Miscellaneous!E12*AWS!C$5> 256, "", Miscellaneous!E12*AWS!C$5) -> 10
H13: c7gd | I13: 3339 | J13: c6gd | K13: =If(C$20 = 0, Ceiling(($C$19 / VLOOKUp(Concat("$", Concat(J13, ".Search")) ,U$4:AB$780, 4, false) * VLOOKUp(Concat("$", Concat(J13, ".Search")) ,U$4:AB$780, 8, false) / AZ),1) * AZ, If(VLOOKUp(Concat("$", Concat(J13, ".Search")) ,U$4:AB$780, 5, false) = 0 , "N/A", Max( Ceiling(($C$20 / (VLOOKUp(Concat("$", Concat(J13, ".Search")) ,U$4:AB$780, 5, false) * VLOOKUp(Concat("$", Concat(J13, ".Search")) ,U$4:AB$780, 6, false)* (1 - DiskOverprovisioning))) / AZ,1) * AZ , Ceiling(($C$19 / VLOOKUp(Concat("$", Concat(J13, ".Search")) ,U$4:AB$780, 4, false) / AZ),1) * AZ ) * VLOOKUp(Concat("$", Concat(J13, ".Search")) ,U$4:AB$780, 8, false) ) ) -> 2825.8 | M13: c5ad | N13: 15.9375 | O13: 10.900697 | P13: =VLOOKUp(Concat("$", Concat(Q13, ".Search")) ,U$4:AB$780, 5, false) * VLOOKUp(Concat("$", Concat(Q13, ".Search")) ,U$4:AB$780, 6, false) * (1 - $C$12)/ VLOOKUp(Concat("$", Concat(Q13, ".Search")) ,U$4:AB$780, 4, false) -> 25.234375 | Q13: c6gd | R13: =if(P13=0, "N/A", P13) -> 25.234375 | S13: =if(P13=0, "N/A", Abs(P13-$C$21)) -> 1.6038217 | U13: $c3. | V13: c3.8xlarge | W13: 32 | X13: 60 | Y13: 320 | Z13: 2 | AA13: 10 Gigabit | AB13: 852.64 | AD13: =if(Miscellaneous!E13*AWS!C$5> 256, "", Miscellaneous!E13*AWS!C$5) -> 11
B14: Additional Resources Required for Resiliency | H14: is4gen | I14: 3443.16 | J14: c6gn | K14: =If(C$20 = 0, Ceiling(($C$19 / VLOOKUp(Concat("$", Concat(J14, ".Search")) ,U$4:AB$780, 4, false) * VLOOKUp(Concat("$", Concat(J14, ".Search")) ,U$4:AB$780, 8, false) / AZ),1) * AZ, If(VLOOKUp(Concat("$", Concat(J14, ".Search")) ,U$4:AB$780, 5, false) = 0 , "N/A", Max( Ceiling(($C$20 / (VLOOKUp(Concat("$", Concat(J14, ".Search")) ,U$4:AB$780, 5, false) * VLOOKUp(Concat("$", Concat(J14, ".Search")) ,U$4:AB$780, 6, false)* (1 - DiskOverprovisioning))) / AZ,1) * AZ , Ceiling(($C$19 / VLOOKUp(Concat("$", Concat(J14, ".Search")) ,U$4:AB$780, 4, false) / AZ),1) * AZ ) * VLOOKUp(Concat("$", Concat(J14, ".Search")) ,U$4:AB$780, 8, false) ) ) -> N/A | M14: m6gd | N14: 12.617188 | O14: 14.221009 | P14: =VLOOKUp(Concat("$", Concat(Q14, ".Search")) ,U$4:AB$780, 5, false) * VLOOKUp(Concat("$", Concat(Q14, ".Search")) ,U$4:AB$780, 6, false) * (1 - $C$12)/ VLOOKUp(Concat("$", Concat(Q14, ".Search")) ,U$4:AB$780, 4, false) -> 0 | Q14: c6gn | R14: =if(P14=0, "N/A", P14) -> N/A | S14: =if(P14=0, "N/A", Abs(P14-$C$21)) -> N/A | U14: $c4.Search | V14: c4.large | W14: 2 | X14: 3.75 | Y14: 0 | Z14: 0 | AA14: Moderate | AB14: 45.99 | AD14: =if(Miscellaneous!E14*AWS!C$5> 256, "", Miscellaneous!E14*AWS!C$5) -> 12
B15: Multiplier | C15: =Switch(ResiliencyTarget, "None", 1, "Rack/AZ", (AZ/(AZ-C6)), "Node", (InstanceCount/(InstanceCount-NodeFailure))) -> 1 | H15: c6id | I15: 3709.9 | J15: c6i | K15: =If(C$20 = 0, Ceiling(($C$19 / VLOOKUp(Concat("$", Concat(J15, ".Search")) ,U$4:AB$780, 4, false) * VLOOKUp(Concat("$", Concat(J15, ".Search")) ,U$4:AB$780, 8, false) / AZ),1) * AZ, If(VLOOKUp(Concat("$", Concat(J15, ".Search")) ,U$4:AB$780, 5, false) = 0 , "N/A", Max( Ceiling(($C$20 / (VLOOKUp(Concat("$", Concat(J15, ".Search")) ,U$4:AB$780, 5, false) * VLOOKUp(Concat("$", Concat(J15, ".Search")) ,U$4:AB$780, 6, false)* (1 - DiskOverprovisioning))) / AZ,1) * AZ , Ceiling(($C$19 / VLOOKUp(Concat("$", Concat(J15, ".Search")) ,U$4:AB$780, 4, false) / AZ),1) * AZ ) * VLOOKUp(Concat("$", Concat(J15, ".Search")) ,U$4:AB$780, 8, false) ) ) -> N/A | M15: m6id | N15: 12.617188 | O15: 14.221009 | P15: =VLOOKUp(Concat("$", Concat(Q15, ".Search")) ,U$4:AB$780, 5, false) * VLOOKUp(Concat("$", Concat(Q15, ".Search")) ,U$4:AB$780, 6, false) * (1 - $C$12)/ VLOOKUp(Concat("$", Concat(Q15, ".Search")) ,U$4:AB$780, 4, false) -> 0 | Q15: c6i | R15: =if(P15=0, "N/A", P15) -> N/A | S15: =if(P15=0, "N/A", Abs(P15-$C$21)) -> N/A | U15: $c4. | V15: c4.xlarge | W15: 4 | X15: 7.5 | Y15: 0 | Z15: 0 | AA15: High | AB15: 91.98 | AD15: =if(Miscellaneous!E15*AWS!C$5> 256, "", Miscellaneous!E15*AWS!C$5) -> 13
H16: c8gd | I16: 3770.6 | J16: c6id | K16: =If(C$20 = 0, Ceiling(($C$19 / VLOOKUp(Concat("$", Concat(J16, ".Search")) ,U$4:AB$780, 4, false) * VLOOKUp(Concat("$", Concat(J16, ".Search")) ,U$4:AB$780, 8, false) / AZ),1) * AZ, If(VLOOKUp(Concat("$", Concat(J16, ".Search")) ,U$4:AB$780, 5, false) = 0 , "N/A", Max( Ceiling(($C$20 / (VLOOKUp(Concat("$", Concat(J16, ".Search")) ,U$4:AB$780, 5, false) * VLOOKUp(Concat("$", Concat(J16, ".Search")) ,U$4:AB$780, 6, false)* (1 - DiskOverprovisioning))) / AZ,1) * AZ , Ceiling(($C$19 / VLOOKUp(Concat("$", Concat(J16, ".Search")) ,U$4:AB$780, 4, false) / AZ),1) * AZ ) * VLOOKUp(Concat("$", Concat(J16, ".Search")) ,U$4:AB$780, 8, false) ) ) -> 3709.9 | M16: m6idn | N16: 12.617188 | O16: 14.221009 | P16: =VLOOKUp(Concat("$", Concat(Q16, ".Search")) ,U$4:AB$780, 5, false) * VLOOKUp(Concat("$", Concat(Q16, ".Search")) ,U$4:AB$780, 6, false) * (1 - $C$12)/ VLOOKUp(Concat("$", Concat(Q16, ".Search")) ,U$4:AB$780, 4, false) -> 25.234375 | Q16: c6id | R16: =if(P16=0, "N/A", P16) -> 25.234375 | S16: =if(P16=0, "N/A", Abs(P16-$C$21)) -> 1.6038217 | U16: $c4. | V16: c4.2xlarge | W16: 8 | X16: 15 | Y16: 0 | Z16: 0 | AA16: High | AB16: 183.96 | AD16: =if(Miscellaneous!E16*AWS!C$5> 256, "", Miscellaneous!E16*AWS!C$5) -> 14
B17: Requirements | E17: Total Available Hardware Capacity | H17: m7gd | I17: 3928.9 | J17: c6in | K17: =If(C$20 = 0, Ceiling(($C$19 / VLOOKUp(Concat("$", Concat(J17, ".Search")) ,U$4:AB$780, 4, false) * VLOOKUp(Concat("$", Concat(J17, ".Search")) ,U$4:AB$780, 8, false) / AZ),1) * AZ, If(VLOOKUp(Concat("$", Concat(J17, ".Search")) ,U$4:AB$780, 5, false) = 0 , "N/A", Max( Ceiling(($C$20 / (VLOOKUp(Concat("$", Concat(J17, ".Search")) ,U$4:AB$780, 5, false) * VLOOKUp(Concat("$", Concat(J17, ".Search")) ,U$4:AB$780, 6, false)* (1 - DiskOverprovisioning))) / AZ,1) * AZ , Ceiling(($C$19 / VLOOKUp(Concat("$", Concat(J17, ".Search")) ,U$4:AB$780, 4, false) / AZ),1) * AZ ) * VLOOKUp(Concat("$", Concat(J17, ".Search")) ,U$4:AB$780, 8, false) ) ) -> N/A | M17: m7gd | N17: 12.617188 | O17: 14.221009 | P17: =VLOOKUp(Concat("$", Concat(Q17, ".Search")) ,U$4:AB$780, 5, false) * VLOOKUp(Concat("$", Concat(Q17, ".Search")) ,U$4:AB$780, 6, false) * (1 - $C$12)/ VLOOKUp(Concat("$", Concat(Q17, ".Search")) ,U$4:AB$780, 4, false) -> 0 | Q17: c6in | R17: =if(P17=0, "N/A", P17) -> N/A | S17: =if(P17=0, "N/A", Abs(P17-$C$21)) -> N/A | U17: $c4. | V17: c4.4xlarge | W17: 16 | X17: 30 | Y17: 0 | Z17: 0 | AA17: High | AB17: 367.92 | AD17: =if(Miscellaneous!E17*AWS!C$5> 256, "", Miscellaneous!E17*AWS!C$5) -> 15
B18: Hardware Requirements | E18: Ram and Disk Size | H18: r6gd | I18: 4238.4 | J18: c7a | K18: =If(C$20 = 0, Ceiling(($C$19 / VLOOKUp(Concat("$", Concat(J18, ".Search")) ,U$4:AB$780, 4, false) * VLOOKUp(Concat("$", Concat(J18, ".Search")) ,U$4:AB$780, 8, false) / AZ),1) * AZ, If(VLOOKUp(Concat("$", Concat(J18, ".Search")) ,U$4:AB$780, 5, false) = 0 , "N/A", Max( Ceiling(($C$20 / (VLOOKUp(Concat("$", Concat(J18, ".Search")) ,U$4:AB$780, 5, false) * VLOOKUp(Concat("$", Concat(J18, ".Search")) ,U$4:AB$780, 6, false)* (1 - DiskOverprovisioning))) / AZ,1) * AZ , Ceiling(($C$19 / VLOOKUp(Concat("$", Concat(J18, ".Search")) ,U$4:AB$780, 4, false) / AZ),1) * AZ ) * VLOOKUp(Concat("$", Concat(J18, ".Search")) ,U$4:AB$780, 8, false) ) ) -> N/A | M18: m8gd | N18: 12.617188 | O18: 14.221009 | P18: =VLOOKUp(Concat("$", Concat(Q18, ".Search")) ,U$4:AB$780, 5, false) * VLOOKUp(Concat("$", Concat(Q18, ".Search")) ,U$4:AB$780, 6, false) * (1 - $C$12)/ VLOOKUp(Concat("$", Concat(Q18, ".Search")) ,U$4:AB$780, 4, false) -> 0 | Q18: c7a | R18: =if(P18=0, "N/A", P18) -> N/A | S18: =if(P18=0, "N/A", Abs(P18-$C$21)) -> N/A | U18: $c4. | V18: c4.8xlarge | W18: 36 | X18: 60 | Y18: 0 | Z18: 0 | AA18: 10 Gigabit | AB18: 735.84 | AD18: =if(Miscellaneous!E18*AWS!C$5> 256, "", Miscellaneous!E18*AWS!C$5) -> 16
B19: =Workload!B62 -> Minimum Ram Required (GB) | C19: =MinRam * Multiplier -> 286.14396 | E19: Total RAM (GB) | F19: =InstanceCount*InstanceRamSize -> 15 | H19: m6id | I19: 4365.4 | J19: c7g | K19: =If(C$20 = 0, Ceiling(($C$19 / VLOOKUp(Concat("$", Concat(J19, ".Search")) ,U$4:AB$780, 4, false) * VLOOKUp(Concat("$", Concat(J19, ".Search")) ,U$4:AB$780, 8, false) / AZ),1) * AZ, If(VLOOKUp(Concat("$", Concat(J19, ".Search")) ,U$4:AB$780, 5, false) = 0 , "N/A", Max( Ceiling(($C$20 / (VLOOKUp(Concat("$", Concat(J19, ".Search")) ,U$4:AB$780, 5, false) * VLOOKUp(Concat("$", Concat(J19, ".Search")) ,U$4:AB$780, 6, false)* (1 - DiskOverprovisioning))) / AZ,1) * AZ , Ceiling(($C$19 / VLOOKUp(Concat("$", Concat(J19, ".Search")) ,U$4:AB$780, 4, false) / AZ),1) * AZ ) * VLOOKUp(Concat("$", Concat(J19, ".Search")) ,U$4:AB$780, 8, false) ) ) -> N/A | M19: c5d | N19: 10.625 | O19: 16.213197 | P19: =VLOOKUp(Concat("$", Concat(Q19, ".Search")) ,U$4:AB$780, 5, false) * VLOOKUp(Concat("$", Concat(Q19, ".Search")) ,U$4:AB$780, 6, false) * (1 - $C$12)/ VLOOKUp(Concat("$", Concat(Q19, ".Search")) ,U$4:AB$780, 4, false) -> 0 | Q19: c7g | R19: =if(P19=0, "N/A", P19) -> N/A | S19: =if(P19=0, "N/A", Abs(P19-$C$21)) -> N/A | U19: $c5.Search | V19: c5.large | W19: 2 | X19: 4 | Y19: 0 | Z19: 0 | AA19: Up to 10 Gigabit | AB19: 39.42 | AD19: =if(Miscellaneous!E19*AWS!C$5> 256, "", Miscellaneous!E19*AWS!C$5) -> 17
B20: =Workload!B63 -> Minimum Disk Required (GB) | C20: =MinDisk * Multiplier -> 7679.5879 | E20: Total DISK (GB) | F20: =InstanceCount*InstanceDiskSize * (1 - DiskOverprovisioning) -> 13.6 | H20: m8gd | I20: 4437.9 | J20: c7gd | K20: =If(C$20 = 0, Ceiling(($C$19 / VLOOKUp(Concat("$", Concat(J20, ".Search")) ,U$4:AB$780, 4, false) * VLOOKUp(Concat("$", Concat(J20, ".Search")) ,U$4:AB$780, 8, false) / AZ),1) * AZ, If(VLOOKUp(Concat("$", Concat(J20, ".Search")) ,U$4:AB$780, 5, false) = 0 , "N/A", Max( Ceiling(($C$20 / (VLOOKUp(Concat("$", Concat(J20, ".Search")) ,U$4:AB$780, 5, false) * VLOOKUp(Concat("$", Concat(J20, ".Search")) ,U$4:AB$780, 6, false)* (1 - DiskOverprovisioning))) / AZ,1) * AZ , Ceiling(($C$19 / VLOOKUp(Concat("$", Concat(J20, ".Search")) ,U$4:AB$780, 4, false) / AZ),1) * AZ ) * VLOOKUp(Concat("$", Concat(J20, ".Search")) ,U$4:AB$780, 8, false) ) ) -> 3339 | M20: c3 | N20: 9.0666667 | O20: 17.77153 | P20: =VLOOKUp(Concat("$", Concat(Q20, ".Search")) ,U$4:AB$780, 5, false) * VLOOKUp(Concat("$", Concat(Q20, ".Search")) ,U$4:AB$780, 6, false) * (1 - $C$12)/ VLOOKUp(Concat("$", Concat(Q20, ".Search")) ,U$4:AB$780, 4, false) -> 25.234375 | Q20: c7gd | R20: =if(P20=0, "N/A", P20) -> 25.234375 | S20: =if(P20=0, "N/A", Abs(P20-$C$21)) -> 1.6038217 | U20: $c5. | V20: c5.xlarge | W20: 4 | X20: 8 | Y20: 0 | Z20: 0 | AA20: Up to 10 Gigabit | AB20: 78.11 | AD20: =if(Miscellaneous!E20*AWS!C$5> 256, "", Miscellaneous!E20*AWS!C$5) -> 18
B21: =Workload!B64 -> Disk to Ram Ratio | C21: =DomainModelDiskToRamRatio -> 26.838197 | E21: Disk to Ram Ratio | F21: =TotalGuaranteedDisk/TotalGuaranteedRam -> 0.90666667 | H21: r7gd | I21: 4994.7 | J21: c7gn | K21: =If(C$20 = 0, Ceiling(($C$19 / VLOOKUp(Concat("$", Concat(J21, ".Search")) ,U$4:AB$780, 4, false) * VLOOKUp(Concat("$", Concat(J21, ".Search")) ,U$4:AB$780, 8, false) / AZ),1) * AZ, If(VLOOKUp(Concat("$", Concat(J21, ".Search")) ,U$4:AB$780, 5, false) = 0 , "N/A", Max( Ceiling(($C$20 / (VLOOKUp(Concat("$", Concat(J21, ".Search")) ,U$4:AB$780, 5, false) * VLOOKUp(Concat("$", Concat(J21, ".Search")) ,U$4:AB$780, 6, false)* (1 - DiskOverprovisioning))) / AZ,1) * AZ , Ceiling(($C$19 / VLOOKUp(Concat("$", Concat(J21, ".Search")) ,U$4:AB$780, 4, false) / AZ),1) * AZ ) * VLOOKUp(Concat("$", Concat(J21, ".Search")) ,U$4:AB$780, 8, false) ) ) -> N/A | M21: g4ad | N21: 7.96875 | O21: 18.869447 | P21: =VLOOKUp(Concat("$", Concat(Q21, ".Search")) ,U$4:AB$780, 5, false) * VLOOKUp(Concat("$", Concat(Q21, ".Search")) ,U$4:AB$780, 6, false) * (1 - $C$12)/ VLOOKUp(Concat("$", Concat(Q21, ".Search")) ,U$4:AB$780, 4, false) -> 0 | Q21: c7gn | R21: =if(P21=0, "N/A", P21) -> N/A | S21: =if(P21=0, "N/A", Abs(P21-$C$21)) -> N/A | U21: $c5. | V21: c5.2xlarge | W21: 8 | X21: 16 | Y21: 0 | Z21: 0 | AA21: Up to 10 Gigabit | AB21: 156.22 | AD21: =if(Miscellaneous!E21*AWS!C$5> 256, "", Miscellaneous!E21*AWS!C$5) -> 19
B22: =Workload!B92 -> Throughput | E22: Throughput and IOPS | H22: c5ad | I22: 5063.28 | J22: c7i-flex | K22: =If(C$20 = 0, Ceiling(($C$19 / VLOOKUp(Concat("$", Concat(J22, ".Search")) ,U$4:AB$780, 4, false) * VLOOKUp(Concat("$", Concat(J22, ".Search")) ,U$4:AB$780, 8, false) / AZ),1) * AZ, If(VLOOKUp(Concat("$", Concat(J22, ".Search")) ,U$4:AB$780, 5, false) = 0 , "N/A", Max( Ceiling(($C$20 / (VLOOKUp(Concat("$", Concat(J22, ".Search")) ,U$4:AB$780, 5, false) * VLOOKUp(Concat("$", Concat(J22, ".Search")) ,U$4:AB$780, 6, false)* (1 - DiskOverprovisioning))) / AZ,1) * AZ , Ceiling(($C$19 / VLOOKUp(Concat("$", Concat(J22, ".Search")) ,U$4:AB$780, 4, false) / AZ),1) * AZ ) * VLOOKUp(Concat("$", Concat(J22, ".Search")) ,U$4:AB$780, 8, false) ) ) -> N/A | M22: m5ad | N22: 7.96875 | O22: 18.869447 | P22: =VLOOKUp(Concat("$", Concat(Q22, ".Search")) ,U$4:AB$780, 5, false) * VLOOKUp(Concat("$", Concat(Q22, ".Search")) ,U$4:AB$780, 6, false) * (1 - $C$12)/ VLOOKUp(Concat("$", Concat(Q22, ".Search")) ,U$4:AB$780, 4, false) -> 0 | Q22: c7i-flex | R22: =if(P22=0, "N/A", P22) -> N/A | S22: =if(P22=0, "N/A", Abs(P22-$C$21)) -> N/A | U22: $c5. | V22: c5.4xlarge | W22: 16 | X22: 32 | Y22: 0 | Z22: 0 | AA22: Up to 10 Gigabit | AB22: 312.44 | AD22: =if(Miscellaneous!E22*AWS!C$5> 256, "", Miscellaneous!E22*AWS!C$5) -> 20
B23: Peak Throughput (MB/s) | C23: =(PeakDiskReadThroughput + PeakDiskWriteThroughput) * Multiplier -> 4155.2734 | E23: Peak Throughput (MB/s) | F23: =InstanceThroughput*InstanceCount -> 300 | H23: r6id | I23: 5549.5 | J23: c7i | K23: =If(C$20 = 0, Ceiling(($C$19 / VLOOKUp(Concat("$", Concat(J23, ".Search")) ,U$4:AB$780, 4, false) * VLOOKUp(Concat("$", Concat(J23, ".Search")) ,U$4:AB$780, 8, false) / AZ),1) * AZ, If(VLOOKUp(Concat("$", Concat(J23, ".Search")) ,U$4:AB$780, 5, false) = 0 , "N/A", Max( Ceiling(($C$20 / (VLOOKUp(Concat("$", Concat(J23, ".Search")) ,U$4:AB$780, 5, false) * VLOOKUp(Concat("$", Concat(J23, ".Search")) ,U$4:AB$780, 6, false)* (1 - DiskOverprovisioning))) / AZ,1) * AZ , Ceiling(($C$19 / VLOOKUp(Concat("$", Concat(J23, ".Search")) ,U$4:AB$780, 4, false) / AZ),1) * AZ ) * VLOOKUp(Concat("$", Concat(J23, ".Search")) ,U$4:AB$780, 8, false) ) ) -> N/A | M23: m5d | N23: 7.96875 | O23: 18.869447 | P23: =VLOOKUp(Concat("$", Concat(Q23, ".Search")) ,U$4:AB$780, 5, false) * VLOOKUp(Concat("$", Concat(Q23, ".Search")) ,U$4:AB$780, 6, false) * (1 - $C$12)/ VLOOKUp(Concat("$", Concat(Q23, ".Search")) ,U$4:AB$780, 4, false) -> 0 | Q23: c7i | R23: =if(P23=0, "N/A", P23) -> N/A | S23: =if(P23=0, "N/A", Abs(P23-$C$21)) -> N/A | U23: $c5. | V23: c5.9xlarge | W23: 36 | X23: 72 | Y23: 0 | Z23: 0 | AA23: 12 Gigabit | AB23: 703.72 | AD23: =if(Miscellaneous!E23*AWS!C$5> 256, "", Miscellaneous!E23*AWS!C$5) -> 21
B24: Peak IOPS (K) | C24: =(PeakReadIOPS + PeakWriteIOPS*RF_1)*Multiplier -> 1196.608 | E24: Estimated IOPS (K) | F24: =InstanceIOPS*InstanceCount -> 64 | H24: r8gd | I24: 5655.5 | J24: c8g | K24: =If(C$20 = 0, Ceiling(($C$19 / VLOOKUp(Concat("$", Concat(J24, ".Search")) ,U$4:AB$780, 4, false) * VLOOKUp(Concat("$", Concat(J24, ".Search")) ,U$4:AB$780, 8, false) / AZ),1) * AZ, If(VLOOKUp(Concat("$", Concat(J24, ".Search")) ,U$4:AB$780, 5, false) = 0 , "N/A", Max( Ceiling(($C$20 / (VLOOKUp(Concat("$", Concat(J24, ".Search")) ,U$4:AB$780, 5, false) * VLOOKUp(Concat("$", Concat(J24, ".Search")) ,U$4:AB$780, 6, false)* (1 - DiskOverprovisioning))) / AZ,1) * AZ , Ceiling(($C$19 / VLOOKUp(Concat("$", Concat(J24, ".Search")) ,U$4:AB$780, 4, false) / AZ),1) * AZ ) * VLOOKUp(Concat("$", Concat(J24, ".Search")) ,U$4:AB$780, 8, false) ) ) -> N/A | M24: m5dn | N24: 7.96875 | O24: 18.869447 | P24: =VLOOKUp(Concat("$", Concat(Q24, ".Search")) ,U$4:AB$780, 5, false) * VLOOKUp(Concat("$", Concat(Q24, ".Search")) ,U$4:AB$780, 6, false) * (1 - $C$12)/ VLOOKUp(Concat("$", Concat(Q24, ".Search")) ,U$4:AB$780, 4, false) -> 0 | Q24: c8g | R24: =if(P24=0, "N/A", P24) -> N/A | S24: =if(P24=0, "N/A", Abs(P24-$C$21)) -> N/A | U24: $c5. | V24: c5.12xlarge | W24: 48 | X24: 96 | Y24: 0 | Z24: 0 | AA24: 12 Gigabit | AB24: 938.05 | AD24: =if(Miscellaneous!E24*AWS!C$5> 256, "", Miscellaneous!E24*AWS!C$5) -> 22
B25: Cache Size | E25: Other | H25: m6idn | I25: 5854.3 | J25: c8gd | K25: =If(C$20 = 0, Ceiling(($C$19 / VLOOKUp(Concat("$", Concat(J25, ".Search")) ,U$4:AB$780, 4, false) * VLOOKUp(Concat("$", Concat(J25, ".Search")) ,U$4:AB$780, 8, false) / AZ),1) * AZ, If(VLOOKUp(Concat("$", Concat(J25, ".Search")) ,U$4:AB$780, 5, false) = 0 , "N/A", Max( Ceiling(($C$20 / (VLOOKUp(Concat("$", Concat(J25, ".Search")) ,U$4:AB$780, 5, false) * VLOOKUp(Concat("$", Concat(J25, ".Search")) ,U$4:AB$780, 6, false)* (1 - DiskOverprovisioning))) / AZ,1) * AZ , Ceiling(($C$19 / VLOOKUp(Concat("$", Concat(J25, ".Search")) ,U$4:AB$780, 4, false) / AZ),1) * AZ ) * VLOOKUp(Concat("$", Concat(J25, ".Search")) ,U$4:AB$780, 8, false) ) ) -> 3770.6 | M25: r6gd | N25: 6.3085938 | O25: 20.529603 | P25: =VLOOKUp(Concat("$", Concat(Q25, ".Search")) ,U$4:AB$780, 5, false) * VLOOKUp(Concat("$", Concat(Q25, ".Search")) ,U$4:AB$780, 6, false) * (1 - $C$12)/ VLOOKUp(Concat("$", Concat(Q25, ".Search")) ,U$4:AB$780, 4, false) -> 25.234375 | Q25: c8gd | R25: =if(P25=0, "N/A", P25) -> 25.234375 | S25: =if(P25=0, "N/A", Abs(P25-$C$21)) -> 1.6038217 | U25: $c5. | V25: c5.18xlarge | W25: 72 | X25: 144 | Y25: 0 | Z25: 0 | AA25: 25 Gigabit | AB25: 1407.44 | AD25: =if(Miscellaneous!E25*AWS!C$5> 256, "", Miscellaneous!E25*AWS!C$5) -> 23
B26: Page Cache Size for On-Disk SI (GB) | C26: =PageCacheSize -> 0 | E26: Number of CPUs | F26: =InstanceCount*InstanceCpuCount -> 4 | H26: x2gd | I26: 6010.1 | J26: g4ad | K26: =If(C$20 = 0, Ceiling(($C$19 / VLOOKUp(Concat("$", Concat(J26, ".Search")) ,U$4:AB$780, 4, false) * VLOOKUp(Concat("$", Concat(J26, ".Search")) ,U$4:AB$780, 8, false) / AZ),1) * AZ, If(VLOOKUp(Concat("$", Concat(J26, ".Search")) ,U$4:AB$780, 5, false) = 0 , "N/A", Max( Ceiling(($C$20 / (VLOOKUp(Concat("$", Concat(J26, ".Search")) ,U$4:AB$780, 5, false) * VLOOKUp(Concat("$", Concat(J26, ".Search")) ,U$4:AB$780, 6, false)* (1 - DiskOverprovisioning))) / AZ,1) * AZ , Ceiling(($C$19 / VLOOKUp(Concat("$", Concat(J26, ".Search")) ,U$4:AB$780, 4, false) / AZ),1) * AZ ) * VLOOKUp(Concat("$", Concat(J26, ".Search")) ,U$4:AB$780, 8, false) ) ) -> 6379.68 | M26: r6id | N26: 6.3085938 | O26: 20.529603 | P26: =VLOOKUp(Concat("$", Concat(Q26, ".Search")) ,U$4:AB$780, 5, false) * VLOOKUp(Concat("$", Concat(Q26, ".Search")) ,U$4:AB$780, 6, false) * (1 - $C$12)/ VLOOKUp(Concat("$", Concat(Q26, ".Search")) ,U$4:AB$780, 4, false) -> 7.96875 | Q26: g4ad | R26: =if(P26=0, "N/A", P26) -> 7.96875 | S26: =if(P26=0, "N/A", Abs(P26-$C$21)) -> 18.869447 | U26: $c5. | V26: c5.24xlarge | W26: 96 | X26: 192 | Y26: 0 | Z26: 0 | AA26: 25 Gigabit | AB26: 1876.1 | AD26: =if(Miscellaneous!E26*AWS!C$5> 256, "", Miscellaneous!E26*AWS!C$5) -> 25
E27: Number of Disks | F27: =InstanceDiskCount*InstanceCount -> 0.2 | H27: m5ad | I27: 6061.92 | J27: g4dn | K27: =If(C$20 = 0, Ceiling(($C$19 / VLOOKUp(Concat("$", Concat(J27, ".Search")) ,U$4:AB$780, 4, false) * VLOOKUp(Concat("$", Concat(J27, ".Search")) ,U$4:AB$780, 8, false) / AZ),1) * AZ, If(VLOOKUp(Concat("$", Concat(J27, ".Search")) ,U$4:AB$780, 5, false) = 0 , "N/A", Max( Ceiling(($C$20 / (VLOOKUp(Concat("$", Concat(J27, ".Search")) ,U$4:AB$780, 5, false) * VLOOKUp(Concat("$", Concat(J27, ".Search")) ,U$4:AB$780, 6, false)* (1 - DiskOverprovisioning))) / AZ,1) * AZ , Ceiling(($C$19 / VLOOKUp(Concat("$", Concat(J27, ".Search")) ,U$4:AB$780, 4, false) / AZ),1) * AZ ) * VLOOKUp(Concat("$", Concat(J27, ".Search")) ,U$4:AB$780, 8, false) ) ) -> 22716.87 | M27: r6idn | N27: 6.3085938 | O27: 20.529603 | P27: =VLOOKUp(Concat("$", Concat(Q27, ".Search")) ,U$4:AB$780, 5, false) * VLOOKUp(Concat("$", Concat(Q27, ".Search")) ,U$4:AB$780, 6, false) * (1 - $C$12)/ VLOOKUp(Concat("$", Concat(Q27, ".Search")) ,U$4:AB$780, 4, false) -> 2.9882812 | Q27: g4dn | R27: =if(P27=0, "N/A", P27) -> 2.9882812 | S27: =if(P27=0, "N/A", Abs(P27-$C$21)) -> 23.849915 | U27: $c5a.Search | V27: c5a.large | W27: 2 | X27: 4 | Y27: 0 | Z27: 0 | AA27: Up to 10 Gigabit | AB27: 35.77 | AD27: =if(Miscellaneous!E27*AWS!C$5> 256, "", Miscellaneous!E27*AWS!C$5) -> 26
B28: AWS Networking | H28: g4ad | I28: 6379.68 | J28: g5 | K28: =If(C$20 = 0, Ceiling(($C$19 / VLOOKUp(Concat("$", Concat(J28, ".Search")) ,U$4:AB$780, 4, false) * VLOOKUp(Concat("$", Concat(J28, ".Search")) ,U$4:AB$780, 8, false) / AZ),1) * AZ, If(VLOOKUp(Concat("$", Concat(J28, ".Search")) ,U$4:AB$780, 5, false) = 0 , "N/A", Max( Ceiling(($C$20 / (VLOOKUp(Concat("$", Concat(J28, ".Search")) ,U$4:AB$780, 5, false) * VLOOKUp(Concat("$", Concat(J28, ".Search")) ,U$4:AB$780, 6, false)* (1 - DiskOverprovisioning))) / AZ,1) * AZ , Ceiling(($C$19 / VLOOKUp(Concat("$", Concat(J28, ".Search")) ,U$4:AB$780, 4, false) / AZ),1) * AZ ) * VLOOKUp(Concat("$", Concat(J28, ".Search")) ,U$4:AB$780, 8, false) ) ) -> 7825.65 | M28: r7gd | N28: 6.3085938 | O28: 20.529603 | P28: =VLOOKUp(Concat("$", Concat(Q28, ".Search")) ,U$4:AB$780, 5, false) * VLOOKUp(Concat("$", Concat(Q28, ".Search")) ,U$4:AB$780, 6, false) * (1 - $C$12)/ VLOOKUp(Concat("$", Concat(Q28, ".Search")) ,U$4:AB$780, 4, false) -> 16.822917 | Q28: g5 | R28: =if(P28=0, "N/A", P28) -> 16.822917 | S28: =if(P28=0, "N/A", Abs(P28-$C$21)) -> 10.01528 | U28: $c5a. | V28: c5a.xlarge | W28: 4 | X28: 8 | Y28: 0 | Z28: 0 | AA28: Up to 10 Gigabit | AB28: 70.81 | AD28: =if(Miscellaneous!E28*AWS!C$5> 256, "", Miscellaneous!E28*AWS!C$5) -> 27
B29: Between AZ Egress | H29: m5d | I29: 6657.6 | J29: g5g | K29: =If(C$20 = 0, Ceiling(($C$19 / VLOOKUp(Concat("$", Concat(J29, ".Search")) ,U$4:AB$780, 4, false) * VLOOKUp(Concat("$", Concat(J29, ".Search")) ,U$4:AB$780, 8, false) / AZ),1) * AZ, If(VLOOKUp(Concat("$", Concat(J29, ".Search")) ,U$4:AB$780, 5, false) = 0 , "N/A", Max( Ceiling(($C$20 / (VLOOKUp(Concat("$", Concat(J29, ".Search")) ,U$4:AB$780, 5, false) * VLOOKUp(Concat("$", Concat(J29, ".Search")) ,U$4:AB$780, 6, false)* (1 - DiskOverprovisioning))) / AZ,1) * AZ , Ceiling(($C$19 / VLOOKUp(Concat("$", Concat(J29, ".Search")) ,U$4:AB$780, 4, false) / AZ),1) * AZ ) * VLOOKUp(Concat("$", Concat(J29, ".Search")) ,U$4:AB$780, 8, false) ) ) -> N/A | M29: r8gd | N29: 6.3085938 | O29: 20.529603 | P29: =VLOOKUp(Concat("$", Concat(Q29, ".Search")) ,U$4:AB$780, 5, false) * VLOOKUp(Concat("$", Concat(Q29, ".Search")) ,U$4:AB$780, 6, false) * (1 - $C$12)/ VLOOKUp(Concat("$", Concat(Q29, ".Search")) ,U$4:AB$780, 4, false) -> 0 | Q29: g5g | R29: =if(P29=0, "N/A", P29) -> N/A | S29: =if(P29=0, "N/A", Abs(P29-$C$21)) -> N/A | U29: $c5a. | V29: c5a.2xlarge | W29: 8 | X29: 16 | Y29: 0 | Z29: 0 | AA29: Up to 10 Gigabit | AB29: 141.62 | AD29: =if(Miscellaneous!E29*AWS!C$5> 256, "", Miscellaneous!E29*AWS!C$5) -> 28
B30: Write Request Egress Size(GB) | C30: =(If(AZ=1, 0, ((AZ-1)/AZ) * (AvgRecordSize1*AvgObjWPS1*SecondsInAYear + AvgRecordSize2*AvgObjWPS2*SecondsInAYear + AvgRecordSize3*AvgObjWPS3*SecondsInAYear + AvgRecordSize4*AvgObjWPS4*SecondsInAYear + AvgRecordSize5*AvgObjWPS5*SecondsInAYear) ) /GB) -> 0 | H30: r6idn | I30: 7188.8 | J30: g6 | K30: =If(C$20 = 0, Ceiling(($C$19 / VLOOKUp(Concat("$", Concat(J30, ".Search")) ,U$4:AB$780, 4, false) * VLOOKUp(Concat("$", Concat(J30, ".Search")) ,U$4:AB$780, 8, false) / AZ),1) * AZ, If(VLOOKUp(Concat("$", Concat(J30, ".Search")) ,U$4:AB$780, 5, false) = 0 , "N/A", Max( Ceiling(($C$20 / (VLOOKUp(Concat("$", Concat(J30, ".Search")) ,U$4:AB$780, 5, false) * VLOOKUp(Concat("$", Concat(J30, ".Search")) ,U$4:AB$780, 6, false)* (1 - DiskOverprovisioning))) / AZ,1) * AZ , Ceiling(($C$19 / VLOOKUp(Concat("$", Concat(J30, ".Search")) ,U$4:AB$780, 4, false) / AZ),1) * AZ ) * VLOOKUp(Concat("$", Concat(J30, ".Search")) ,U$4:AB$780, 8, false) ) ) -> 9573 | M30: g6 | N30: 6.2421875 | O30: 20.596009 | P30: =VLOOKUp(Concat("$", Concat(Q30, ".Search")) ,U$4:AB$780, 5, false) * VLOOKUp(Concat("$", Concat(Q30, ".Search")) ,U$4:AB$780, 6, false) * (1 - $C$12)/ VLOOKUp(Concat("$", Concat(Q30, ".Search")) ,U$4:AB$780, 4, false) -> 6.2421875 | Q30: g6 | R30: =if(P30=0, "N/A", P30) -> 6.2421875 | S30: =if(P30=0, "N/A", Abs(P30-$C$21)) -> 20.596009 | U30: $c5a. | V30: c5a.4xlarge | W30: 16 | X30: 32 | Y30: 0 | Z30: 0 | AA30: Up to 10 Gigabit | AB30: 283.24 | AD30: =if(Miscellaneous!E30*AWS!C$5> 256, "", Miscellaneous!E30*AWS!C$5) -> 29
B31: Write Replication Egress Size (GB) | C31: =(IF(AZ=1, 0, (RF_1-1) * (AvgRecordSize1*AvgObjWPS1*SecondsInAYear + AvgRecordSize2*AvgObjWPS2*SecondsInAYear + AvgRecordSize3*AvgObjWPS3*SecondsInAYear + AvgRecordSize4*AvgObjWPS4*SecondsInAYear + AvgRecordSize5*AvgObjWPS5*SecondsInAYear))/GB) -> 0 | H31: r5ad | I31: 7708.8 | J31: g6e | K31: =If(C$20 = 0, Ceiling(($C$19 / VLOOKUp(Concat("$", Concat(J31, ".Search")) ,U$4:AB$780, 4, false) * VLOOKUp(Concat("$", Concat(J31, ".Search")) ,U$4:AB$780, 8, false) / AZ),1) * AZ, If(VLOOKUp(Concat("$", Concat(J31, ".Search")) ,U$4:AB$780, 5, false) = 0 , "N/A", Max( Ceiling(($C$20 / (VLOOKUp(Concat("$", Concat(J31, ".Search")) ,U$4:AB$780, 5, false) * VLOOKUp(Concat("$", Concat(J31, ".Search")) ,U$4:AB$780, 6, false)* (1 - DiskOverprovisioning))) / AZ,1) * AZ , Ceiling(($C$19 / VLOOKUp(Concat("$", Concat(J31, ".Search")) ,U$4:AB$780, 4, false) / AZ),1) * AZ ) * VLOOKUp(Concat("$", Concat(J31, ".Search")) ,U$4:AB$780, 8, false) ) ) -> 22909.48 | M31: m3 | N31: 4.5333333 | O31: 22.304863 | P31: =VLOOKUp(Concat("$", Concat(Q31, ".Search")) ,U$4:AB$780, 5, false) * VLOOKUp(Concat("$", Concat(Q31, ".Search")) ,U$4:AB$780, 6, false) * (1 - $C$12)/ VLOOKUp(Concat("$", Concat(Q31, ".Search")) ,U$4:AB$780, 4, false) -> 2.9882812 | Q31: g6e | R31: =if(P31=0, "N/A", P31) -> 2.9882812 | S31: =if(P31=0, "N/A", Abs(P31-$C$21)) -> 23.849915 | U31: $c5a. | V31: c5a.8xlarge | W31: 32 | X31: 64 | Y31: 0 | Z31: 0 | AA31: 10 Gigabit | AB31: 566.48 | AD31: =if(Miscellaneous!E31*AWS!C$5> 256, "", Miscellaneous!E31*AWS!C$5) -> 30
B32: Read Request Egress Size (GB) | C32: =IF(AZ=1, 0, If(ReadFromNearAZ, IF(RF_1 >= AZ, 0, ((AZ-RF_1)/AZ)), (AZ-1)/AZ)) * (AvgRecordSize1*AvgObjRPS1*(1-NotFoundRate1)*SecondsInAYear + AvgRecordSize2*AvgObjRPS2*(1-NotFoundRate2)*SecondsInAYear + AvgRecordSize3*AvgObjRPS3*(1-NotFoundRate3)*SecondsInAYear + AvgRecordSize4*AvgObjRPS4*(1-NotFoundRate4)*SecondsInAYear + AvgRecordSize5*AvgObjRPS5*(1-NotFoundRate5)*SecondsInAYear )/GB -> 0 | H32: g5 | I32: 7825.65 | J32: gr6 | K32: =If(C$20 = 0, Ceiling(($C$19 / VLOOKUp(Concat("$", Concat(J32, ".Search")) ,U$4:AB$780, 4, false) * VLOOKUp(Concat("$", Concat(J32, ".Search")) ,U$4:AB$780, 8, false) / AZ),1) * AZ, If(VLOOKUp(Concat("$", Concat(J32, ".Search")) ,U$4:AB$780, 5, false) = 0 , "N/A", Max( Ceiling(($C$20 / (VLOOKUp(Concat("$", Concat(J32, ".Search")) ,U$4:AB$780, 5, false) * VLOOKUp(Concat("$", Concat(J32, ".Search")) ,U$4:AB$780, 6, false)* (1 - DiskOverprovisioning))) / AZ,1) * AZ , Ceiling(($C$19 / VLOOKUp(Concat("$", Concat(J32, ".Search")) ,U$4:AB$780, 4, false) / AZ),1) * AZ ) * VLOOKUp(Concat("$", Concat(J32, ".Search")) ,U$4:AB$780, 8, false) ) ) -> 11703.52 | M32: gr6 | N32: 3.984375 | O32: 22.853822 | P32: =VLOOKUp(Concat("$", Concat(Q32, ".Search")) ,U$4:AB$780, 5, false) * VLOOKUp(Concat("$", Concat(Q32, ".Search")) ,U$4:AB$780, 6, false) * (1 - $C$12)/ VLOOKUp(Concat("$", Concat(Q32, ".Search")) ,U$4:AB$780, 4, false) -> 3.984375 | Q32: gr6 | R32: =if(P32=0, "N/A", P32) -> 3.984375 | S32: =if(P32=0, "N/A", Abs(P32-$C$21)) -> 22.853822 | U32: $c5a. | V32: c5a.12xlarge | W32: 48 | X32: 96 | Y32: 0 | Z32: 0 | AA32: 12 Gigabit | AB32: 849.72 | AD32: =if(Miscellaneous!E32*AWS!C$5> 256, "", Miscellaneous!E32*AWS!C$5) -> 31
B33: Cost | H33: m5dn | I33: 8000.8 | J33: hpc7g | K33: =If(C$20 = 0, Ceiling(($C$19 / VLOOKUp(Concat("$", Concat(J33, ".Search")) ,U$4:AB$780, 4, false) * VLOOKUp(Concat("$", Concat(J33, ".Search")) ,U$4:AB$780, 8, false) / AZ),1) * AZ, If(VLOOKUp(Concat("$", Concat(J33, ".Search")) ,U$4:AB$780, 5, false) = 0 , "N/A", Max( Ceiling(($C$20 / (VLOOKUp(Concat("$", Concat(J33, ".Search")) ,U$4:AB$780, 5, false) * VLOOKUp(Concat("$", Concat(J33, ".Search")) ,U$4:AB$780, 6, false)* (1 - DiskOverprovisioning))) / AZ,1) * AZ , Ceiling(($C$19 / VLOOKUp(Concat("$", Concat(J33, ".Search")) ,U$4:AB$780, 4, false) / AZ),1) * AZ ) * VLOOKUp(Concat("$", Concat(J33, ".Search")) ,U$4:AB$780, 8, false) ) ) -> N/A | M33: r5ad | N33: 3.984375 | O33: 22.853822 | P33: =VLOOKUp(Concat("$", Concat(Q33, ".Search")) ,U$4:AB$780, 5, false) * VLOOKUp(Concat("$", Concat(Q33, ".Search")) ,U$4:AB$780, 6, false) * (1 - $C$12)/ VLOOKUp(Concat("$", Concat(Q33, ".Search")) ,U$4:AB$780, 4, false) -> 0 | Q33: hpc7g | R33: =if(P33=0, "N/A", P33) -> N/A | S33: =if(P33=0, "N/A", Abs(P33-$C$21)) -> N/A | U33: $c5a. | V33: c5a.16xlarge | W33: 64 | X33: 128 | Y33: 0 | Z33: 0 | AA33: 20 Gigabit | AB33: 1132.96 | AD33: =if(Miscellaneous!E33*AWS!C$5> 256, "", Miscellaneous!E33*AWS!C$5) -> 32
B34: AZ Data Transfer Cost Per GB | C34: 0.01 | H34: r5d | I34: 8479.68 | J34: i3 | K34: =If(C$20 = 0, Ceiling(($C$19 / VLOOKUp(Concat("$", Concat(J34, ".Search")) ,U$4:AB$780, 4, false) * VLOOKUp(Concat("$", Concat(J34, ".Search")) ,U$4:AB$780, 8, false) / AZ),1) * AZ, If(VLOOKUp(Concat("$", Concat(J34, ".Search")) ,U$4:AB$780, 5, false) = 0 , "N/A", Max( Ceiling(($C$20 / (VLOOKUp(Concat("$", Concat(J34, ".Search")) ,U$4:AB$780, 5, false) * VLOOKUp(Concat("$", Concat(J34, ".Search")) ,U$4:AB$780, 6, false)* (1 - DiskOverprovisioning))) / AZ,1) * AZ , Ceiling(($C$19 / VLOOKUp(Concat("$", Concat(J34, ".Search")) ,U$4:AB$780, 4, false) / AZ),1) * AZ ) * VLOOKUp(Concat("$", Concat(J34, ".Search")) ,U$4:AB$780, 8, false) ) ) -> 1562.2 | M34: r5d | N34: 3.984375 | O34: 22.853822 | P34: =VLOOKUp(Concat("$", Concat(Q34, ".Search")) ,U$4:AB$780, 5, false) * VLOOKUp(Concat("$", Concat(Q34, ".Search")) ,U$4:AB$780, 6, false) * (1 - $C$12)/ VLOOKUp(Concat("$", Concat(Q34, ".Search")) ,U$4:AB$780, 4, false) -> 26.47541 | Q34: i3 | R34: =if(P34=0, "N/A", P34) -> 26.47541 | S34: =if(P34=0, "N/A", Abs(P34-$C$21)) -> 0.36278683 | U34: $c5a. | V34: c5a.24xlarge | W34: 96 | X34: 192 | Y34: 0 | Z34: 0 | AA34: 20 Gigabit | AB34: 1699.44 | AD34: =if(Miscellaneous!E34*AWS!C$5> 256, "", Miscellaneous!E34*AWS!C$5) -> 33
B35: Annual Write Egress Cost | C35: =(AZTransferByWrite+AZTransferByWriteReplication)*AZTransferCost -> 0 | H35: c5d | I35: 8744.67 | J35: i3en | K35: =If(C$20 = 0, Ceiling(($C$19 / VLOOKUp(Concat("$", Concat(J35, ".Search")) ,U$4:AB$780, 4, false) * VLOOKUp(Concat("$", Concat(J35, ".Search")) ,U$4:AB$780, 8, false) / AZ),1) * AZ, If(VLOOKUp(Concat("$", Concat(J35, ".Search")) ,U$4:AB$780, 5, false) = 0 , "N/A", Max( Ceiling(($C$20 / (VLOOKUp(Concat("$", Concat(J35, ".Search")) ,U$4:AB$780, 5, false) * VLOOKUp(Concat("$", Concat(J35, ".Search")) ,U$4:AB$780, 6, false)* (1 - DiskOverprovisioning))) / AZ,1) * AZ , Ceiling(($C$19 / VLOOKUp(Concat("$", Concat(J35, ".Search")) ,U$4:AB$780, 4, false) / AZ),1) * AZ ) * VLOOKUp(Concat("$", Concat(J35, ".Search")) ,U$4:AB$780, 8, false) ) ) -> 2023.56 | M35: r5dn | N35: 3.984375 | O35: 22.853822 | P35: =VLOOKUp(Concat("$", Concat(Q35, ".Search")) ,U$4:AB$780, 5, false) * VLOOKUp(Concat("$", Concat(Q35, ".Search")) ,U$4:AB$780, 6, false) * (1 - $C$12)/ VLOOKUp(Concat("$", Concat(Q35, ".Search")) ,U$4:AB$780, 4, false) -> 66.40625 | Q35: i3en | R35: =if(P35=0, "N/A", P35) -> 66.40625 | S35: =if(P35=0, "N/A", Abs(P35-$C$21)) -> 39.568053 | U35: $c5ad. | V35: c5ad.large | W35: 2 | X35: 4 | Y35: 1900 | Z35: =Z36/2 -> 0.039473684 | AA35: Up to 10 Gigabit | AB35: 39.42 | AD35: =if(Miscellaneous!E35*AWS!C$5> 256, "", Miscellaneous!E35*AWS!C$5) -> 34
B36: Annual Read Egress Cost | C36: =AZTransferByRead*AZTransferCost -> 0 | H36: g6 | I36: 9573 | J36: i4g | K36: =If(C$20 = 0, Ceiling(($C$19 / VLOOKUp(Concat("$", Concat(J36, ".Search")) ,U$4:AB$780, 4, false) * VLOOKUp(Concat("$", Concat(J36, ".Search")) ,U$4:AB$780, 8, false) / AZ),1) * AZ, If(VLOOKUp(Concat("$", Concat(J36, ".Search")) ,U$4:AB$780, 5, false) = 0 , "N/A", Max( Ceiling(($C$20 / (VLOOKUp(Concat("$", Concat(J36, ".Search")) ,U$4:AB$780, 5, false) * VLOOKUp(Concat("$", Concat(J36, ".Search")) ,U$4:AB$780, 6, false)* (1 - DiskOverprovisioning))) / AZ,1) * AZ , Ceiling(($C$19 / VLOOKUp(Concat("$", Concat(J36, ".Search")) ,U$4:AB$780, 4, false) / AZ),1) * AZ ) * VLOOKUp(Concat("$", Concat(J36, ".Search")) ,U$4:AB$780, 8, false) ) ) -> 1463.25 | M36: z1d | N36: 3.984375 | O36: 22.853822 | P36: =VLOOKUp(Concat("$", Concat(Q36, ".Search")) ,U$4:AB$780, 5, false) * VLOOKUp(Concat("$", Concat(Q36, ".Search")) ,U$4:AB$780, 6, false) * (1 - $C$12)/ VLOOKUp(Concat("$", Concat(Q36, ".Search")) ,U$4:AB$780, 4, false) -> 24.902344 | Q36: i4g | R36: =if(P36=0, "N/A", P36) -> 24.902344 | S36: =if(P36=0, "N/A", Abs(P36-$C$21)) -> 1.9358529 | U36: $c5ad. | V36: c5ad.xlarge | W36: 4 | X36: 8 | Y36: 1900 | Z36: =Z37/2 -> 0.078947368 | AA36: Up to 10 Gigabit | AB36: 78.84 | AD36: =if(Miscellaneous!E36*AWS!C$5> 256, "", Miscellaneous!E36*AWS!C$5) -> 35
H37: r5dn | I37: 9834.56 | J37: i4i | K37: =If(C$20 = 0, Ceiling(($C$19 / VLOOKUp(Concat("$", Concat(J37, ".Search")) ,U$4:AB$780, 4, false) * VLOOKUp(Concat("$", Concat(J37, ".Search")) ,U$4:AB$780, 8, false) / AZ),1) * AZ, If(VLOOKUp(Concat("$", Concat(J37, ".Search")) ,U$4:AB$780, 5, false) = 0 , "N/A", Max( Ceiling(($C$20 / (VLOOKUp(Concat("$", Concat(J37, ".Search")) ,U$4:AB$780, 5, false) * VLOOKUp(Concat("$", Concat(J37, ".Search")) ,U$4:AB$780, 6, false)* (1 - DiskOverprovisioning))) / AZ,1) * AZ , Ceiling(($C$19 / VLOOKUp(Concat("$", Concat(J37, ".Search")) ,U$4:AB$780, 4, false) / AZ),1) * AZ ) * VLOOKUp(Concat("$", Concat(J37, ".Search")) ,U$4:AB$780, 8, false) ) ) -> 1624.25 | M37: x2gd | N37: 3.1542969 | O37: 23.6839 | P37: =VLOOKUp(Concat("$", Concat(Q37, ".Search")) ,U$4:AB$780, 5, false) * VLOOKUp(Concat("$", Concat(Q37, ".Search")) ,U$4:AB$780, 6, false) * (1 - $C$12)/ VLOOKUp(Concat("$", Concat(Q37, ".Search")) ,U$4:AB$780, 4, false) -> 24.902344 | Q37: i4i | R37: =if(P37=0, "N/A", P37) -> 24.902344 | S37: =if(P37=0, "N/A", Abs(P37-$C$21)) -> 1.9358529 | U37: $c5ad. | V37: c5ad.2xlarge | W37: 8 | X37: 16 | Y37: 1900 | Z37: =Z38/2 -> 0.15789474 | AA37: Up to 10 Gigabit | AB37: 158.41 | AD37: =if(Miscellaneous!E37*AWS!C$5> 256, "", Miscellaneous!E37*AWS!C$5) -> 36
B38: Summary | H38: z1d | I38: 10776.99 | J38: i7i | K38: =If(C$20 = 0, Ceiling(($C$19 / VLOOKUp(Concat("$", Concat(J38, ".Search")) ,U$4:AB$780, 4, false) * VLOOKUp(Concat("$", Concat(J38, ".Search")) ,U$4:AB$780, 8, false) / AZ),1) * AZ, If(VLOOKUp(Concat("$", Concat(J38, ".Search")) ,U$4:AB$780, 5, false) = 0 , "N/A", Max( Ceiling(($C$20 / (VLOOKUp(Concat("$", Concat(J38, ".Search")) ,U$4:AB$780, 5, false) * VLOOKUp(Concat("$", Concat(J38, ".Search")) ,U$4:AB$780, 6, false)* (1 - DiskOverprovisioning))) / AZ,1) * AZ , Ceiling(($C$19 / VLOOKUp(Concat("$", Concat(J38, ".Search")) ,U$4:AB$780, 4, false) / AZ),1) * AZ ) * VLOOKUp(Concat("$", Concat(J38, ".Search")) ,U$4:AB$780, 8, false) ) ) -> 1815.95 | M38: g4dn | N38: 2.9882812 | O38: 23.849915 | P38: =VLOOKUp(Concat("$", Concat(Q38, ".Search")) ,U$4:AB$780, 5, false) * VLOOKUp(Concat("$", Concat(Q38, ".Search")) ,U$4:AB$780, 6, false) * (1 - $C$12)/ VLOOKUp(Concat("$", Concat(Q38, ".Search")) ,U$4:AB$780, 4, false) -> 24.902344 | Q38: i7i | R38: =if(P38=0, "N/A", P38) -> 24.902344 | S38: =if(P38=0, "N/A", Abs(P38-$C$21)) -> 1.9358529 | U38: $c5ad. | V38: c5ad.4xlarge | W38: 16 | X38: 32 | Y38: 1900 | Z38: =6/19 -> 0.31578947 | AA38: Up to 10 Gigabit | AB38: 316.09 | AD38: =if(Miscellaneous!E38*AWS!C$5> 256, "", Miscellaneous!E38*AWS!C$5) -> 37
B39: Unique Data size (GB) | C39: =UniqueData -> 1144.4092 | H39: gr6 | I39: 11703.52 | J39: i7ie | K39: =If(C$20 = 0, Ceiling(($C$19 / VLOOKUp(Concat("$", Concat(J39, ".Search")) ,U$4:AB$780, 4, false) * VLOOKUp(Concat("$", Concat(J39, ".Search")) ,U$4:AB$780, 8, false) / AZ),1) * AZ, If(VLOOKUp(Concat("$", Concat(J39, ".Search")) ,U$4:AB$780, 5, false) = 0 , "N/A", Max( Ceiling(($C$20 / (VLOOKUp(Concat("$", Concat(J39, ".Search")) ,U$4:AB$780, 5, false) * VLOOKUp(Concat("$", Concat(J39, ".Search")) ,U$4:AB$780, 6, false)* (1 - DiskOverprovisioning))) / AZ,1) * AZ , Ceiling(($C$19 / VLOOKUp(Concat("$", Concat(J39, ".Search")) ,U$4:AB$780, 4, false) / AZ),1) * AZ ) * VLOOKUp(Concat("$", Concat(J39, ".Search")) ,U$4:AB$780, 8, false) ) ) -> 2250.45 | M39: g6e | N39: 2.9882812 | O39: 23.849915 | P39: =VLOOKUp(Concat("$", Concat(Q39, ".Search")) ,U$4:AB$780, 5, false) * VLOOKUp(Concat("$", Concat(Q39, ".Search")) ,U$4:AB$780, 6, false) * (1 - $C$12)/ VLOOKUp(Concat("$", Concat(Q39, ".Search")) ,U$4:AB$780, 4, false) -> 66.40625 | Q39: i7ie | R39: =if(P39=0, "N/A", P39) -> 66.40625 | S39: =if(P39=0, "N/A", Abs(P39-$C$21)) -> 39.568053 | U39: $c5ad.Search | V39: c5ad.8xlarge | W39: 32 | X39: 64 | Y39: 1900 | Z39: =12/19 -> 0.63157895 | AA39: 10 Gigabit | AB39: 632.91 | AD39: =if(Miscellaneous!E39*AWS!C$5> 256, "", Miscellaneous!E39*AWS!C$5) -> 38
B40: Infrastructure | H40: c3 | I40: 12150.12 | J40: i8g | K40: =If(C$20 = 0, Ceiling(($C$19 / VLOOKUp(Concat("$", Concat(J40, ".Search")) ,U$4:AB$780, 4, false) * VLOOKUp(Concat("$", Concat(J40, ".Search")) ,U$4:AB$780, 8, false) / AZ),1) * AZ, If(VLOOKUp(Concat("$", Concat(J40, ".Search")) ,U$4:AB$780, 5, false) = 0 , "N/A", Max( Ceiling(($C$20 / (VLOOKUp(Concat("$", Concat(J40, ".Search")) ,U$4:AB$780, 5, false) * VLOOKUp(Concat("$", Concat(J40, ".Search")) ,U$4:AB$780, 6, false)* (1 - DiskOverprovisioning))) / AZ,1) * AZ , Ceiling(($C$19 / VLOOKUp(Concat("$", Concat(J40, ".Search")) ,U$4:AB$780, 4, false) / AZ),1) * AZ ) * VLOOKUp(Concat("$", Concat(J40, ".Search")) ,U$4:AB$780, 8, false) ) ) -> 1650.95 | M40: r3 | N40: 2.2295082 | O40: 24.608688 | P40: =VLOOKUp(Concat("$", Concat(Q40, ".Search")) ,U$4:AB$780, 5, false) * VLOOKUp(Concat("$", Concat(Q40, ".Search")) ,U$4:AB$780, 6, false) * (1 - $C$12)/ VLOOKUp(Concat("$", Concat(Q40, ".Search")) ,U$4:AB$780, 4, false) -> 24.902344 | Q40: i8g | R40: =if(P40=0, "N/A", P40) -> 24.902344 | S40: =if(P40=0, "N/A", Abs(P40-$C$21)) -> 1.9358529 | U40: $c5ad. | V40: c5ad.12xlarge | W40: 48 | X40: 96 | Y40: 1900 | Z40: =18/19 -> 0.94736842 | AA40: 12 Gigabit | AB40: 949 | AD40: =if(Miscellaneous!E40*AWS!C$5> 256, "", Miscellaneous!E40*AWS!C$5) -> 39
